Workbook

Sheet Scope
A1: Recommendation Product Data Review Scope
A2: Current workbook status | B2: Prepared for multi-batch catalog research with locality-aware seasonality evidence.
A3: Catalog product count | B3: 100
A4: Products missing ProductInfo in seed | B4: 121, 122
A5: Research policy - domestic | B5: Only use extremely trustworthy Vietnam sources.
A6: Research policy - imported | B6: Prefer origin-country primary/industry sources or high-trust international references.
A7: Seasonality rule | B7: Do not compress to a single generic season when a product has multiple windows or locality-specific timing.
A8: Uncertainty rule | B8: Populate the column `Tôi chưa chắc chắn` whenever sources are missing, conflicting, or only partially applicable.
A9: Workbook layout | B9: Products Review = summary per product; Seasonality Evidence = locality/window rows; Research Evidence = non-seasonality claims; Batch Plan = execution order.
A10: Current recommendation caveat | B10: Application code still uses heuristic seasonality based on month + keyword matching, not authoritative crop calendars.

Sheet Batch Plan
A1: Batch | B1: Focus | C1: Criteria | D1: Target Count | E1: Product IDs | F1: Representative Products
A2: B1 | B2: Trái cây nhập khẩu hoặc ngoại nguồn, cần đối chiếu chính xác theo nguồn gốc xuất xứ. | C2: Imported fruits or foreign-origin fruits requiring origin-country sourcing first. | D2: 11 | E2: 61, 62, 63, 68, 71, 73, 74, 75, 76, 77, 78 | F2: Táo Fuji Nhật, Cam Cara ruột đỏ, Nho Mỹ không hạt, Chuối già Nam Mỹ, Măng cụt, Lựu đỏ Mỹ, Dưa lưới Nhật, Mận đỏ Mỹ ...
A3: B2 | B3: Thiếu metadata nền hoặc origin/classification chưa đủ để tra cứu ngoài ngay. | C3: Hybrid-origin/imported non-fruit items or rows blocked by missing seed metadata. | D3: 6 | E3: 46, 52, 53, 115, 121, 122 | F3: Khoai lang Nhật, Nấm hương khô, Nấm linh chi đỏ, Tỏi tây, khoai mỡ, Rau muống
A4: B3 | B4: Trái cây nội địa và đặc sản vùng miền, ưu tiên peak season + khác biệt theo tỉnh/vùng. | C4: Domestic fruits and regional specialties with strong locality-sensitive seasonality. | D4: 12 | E4: 64, 65, 66, 67, 69, 70, 72, 116, 117, 118, 119, 120 | F4: Xoài cát Hòa Lộc, Dưa hấu không hạt, Bơ Booth 7, Dâu tây Đà Lạt, Đu đủ vàng, Thanh long ruột đỏ, Mít Thái siêu ngọt, Chuối già Việt Nam ...
A5: B4 | B5: Rau lá, rau thơm và nhóm thân/mầm; thường có quanh năm nhưng peak và vùng trồng khác nhau. | C5: Leafy greens, herbs, stems and sprouts; often year-round but peak differs by region. | D5: 40 | E5: 1, 2, 3, 4, 5, 6, 7, 8, 9, 15, 16, 17, 18, 19, 20, 21, 22, 30, 31, 32, 33, 34, 35, 36, 37, 38, 39, 55, 56, 57, 58, 59, 60, 101, 102, 103, 104, 105, 113, 114 | F5: Rau muống, Cải bó xôi, Rau lang, Cải thìa, Rau dền đỏ, Bông cải xanh, Súp lơ trắng, Măng tây xanh ...
A6: B5 | B6: Rau ăn quả, củ/rễ, nấm và nhóm còn lại; kiểm tra seasonality/cultivation theo vùng hoặc mô hình trồng. | C6: Domestic fruiting vegetables, roots/tubers, mushrooms and remaining products. | D6: 31 | E6: 10, 11, 12, 13, 14, 23, 24, 25, 26, 27, 28, 29, 40, 41, 42, 43, 44, 45, 47, 48, 49, 50, 51, 54, 106, 107, 108, 109, 110, 111, 112 | F6: Cà chua bi, Dưa leo mini, Bí đỏ, Cà rốt, Khoai tây vàng, Cà tím, Đậu cove, Ớt chuông ...

Sheet Products Review
A1: ProductID | B1: CategoryName | C1: ProductName | D1: Sku | E1: Current Origin | F1: Current Standard | G1: Current Preservation | H1: Current Weight | I1: Current NearExpiryDays | J1: Current ShortDescription | K1: Derived Flavor Profile | L1: Derived Texture Profile | M1: Derived Usage Profile | N1: Current Origin Classification | O1: Recommendation Uses | P1: Proposed External Review Fields | Q1: Research Priority | R1: Batch | S1: Batch Focus | T1: Review Status | U1: Verified Seasonality Summary | V1: Seasonality Locality Count | W1: Seasonality Evidence Count | X1: General Evidence Count | Y1: Verified Origin Country | Z1: Verified Origin Province/Region | AA1: Verified Domestic/Imported | AB1: Verified Standard/Certification | AC1: Verified Preservation Guidance | AD1: Verified Flavor Profile | AE1: Verified Texture Profile | AF1: Verified Usage Profile | AG1: Primary Source URL | AH1: Secondary Source URL | AI1: Thời gian thu thập | AJ1: Tôi chưa chắc chắn | AK1: Reviewer Notes
A2: 1 | B2: Rau lá | C2: Rau muống | D2: VEG-RM-001 | E2: Long An, Việt Nam | F2: VietGAP | G2: Giữ nơi khô mát, tránh ánh nắng, nên dùng trong 2 ngày. | H2: 500g | I2: 5 | J2: Giàu vitamin A, C, chất xơ và sắt... Tươi xanh, thân giòn, lá non, trồng sạch không thuốc. | K2: Tự nhiên | L2: Giòn | M2: Xào / nấu canh | N2: Nội địa | O2: Origin|Standard|Preservation|Weight|Attributes|Seasonality heuristic | P2: Origin; Season window; Standard/cert; Preservation guidance; Flavor/Texture/Usage | Q2: Trung bình | R2: B4 | S2: Rau lá, rau thơm và nhóm thân/mầm; thường có quanh năm nhưng peak và vùng trồng khác nhau. | T2: Pending | V2: =COUNTIF('Seasonality Evidence'!B:B,A2) | W2: =COUNTIF('Seasonality Evidence'!B:B,A2) | X2: =COUNTIF('Research Evidence'!B:B,A2)
A3: 2 | B3: Rau lá | C3: Cải bó xôi | D3: VEG-CBX-002 | E3: Đà Lạt, Việt Nam | F3: GlobalGAP | G3: Bảo quản trong ngăn mát 2–5°C, không để úng nước. | H3: 300g | J3: Giàu vitamin A, C, K và sắt... Lá xanh sẫm, tươi giòn, dinh dưỡng cao. | K3: Tự nhiên | L3: Giòn | M3: Salad / ăn sống | N3: Nội địa | O3: Origin|Standard|Preservation|Weight|Attributes|Seasonality heuristic | P3: Origin; Season window; Standard/cert; Preservation guidance; Flavor/Texture/Usage | Q3: Trung bình | R3: B4 | S3: Rau lá, rau thơm và nhóm thân/mầm; thường có quanh năm nhưng peak và vùng trồng khác nhau. | T3: Pending | V3: =COUNTIF('Seasonality Evidence'!B:B,A3) | W3: =COUNTIF('Seasonality Evidence'!B:B,A3) | X3: =COUNTIF('Research Evidence'!B:B,A3)
A4: 3 | B4: Rau lá | C4: Rau lang | D4: VEG-RL-003 | E4: Tiền Giang, Việt Nam | F4: VietGAP | G4: Để nơi khô thoáng, tránh nắng trực tiếp. | H4: 400g | J4: Giàu chất xơ, vitamin C và canxi... Lá non xanh mướt, giúp thanh lọc cơ thể. | K4: Thanh | L4: Tươi | M4: Xào / nấu canh | N4: Nội địa | O4: Origin|Standard|Preservation|Weight|Attributes|Seasonality heuristic | P4: Origin; Season window; Standard/cert; Preservation guidance; Flavor/Texture/Usage | Q4: Trung bình | R4: B4 | S4: Rau lá, rau thơm và nhóm thân/mầm; thường có quanh năm nhưng peak và vùng trồng khác nhau. | T4: Pending | V4: =COUNTIF('Seasonality Evidence'!B:B,A4) | W4: =COUNTIF('Seasonality Evidence'!B:B,A4) | X4: =COUNTIF('Research Evidence'!B:B,A4)
A5: 4 | B5: Rau lá | C5: Cải thìa | D5: VEG-CT-004 | E5: Đà Lạt, Việt Nam | F5: VietGAP | G5: Bảo quản trong túi kín, ngăn mát tủ lạnh, dùng trong 3 ngày. | H5: 400g | J5: Giàu vitamin A, C, K và kali... Lá xanh tươi, vị ngọt nhẹ, giòn. | K5: Ngọt nhẹ | L5: Giòn | M5: Xào | N5: Nội địa | O5: Origin|Standard|Preservation|Weight|Attributes|Seasonality heuristic | P5: Origin; Season window; Standard/cert; Preservation guidance; Flavor/Texture/Usage | Q5: Trung bình | R5: B4 | S5: Rau lá, rau thơm và nhóm thân/mầm; thường có quanh năm nhưng peak và vùng trồng khác nhau. | T5: Pending | V5: =COUNTIF('Seasonality Evidence'!B:B,A5) | W5: =COUNTIF('Seasonality Evidence'!B:B,A5) | X5: =COUNTIF('Research Evidence'!B:B,A5)
A6: 5 | B6: Rau lá | C6: Rau dền đỏ | D6: VEG-RDD-005 | E6: Đồng Nai, Việt Nam | F6: OCOP 4 sao | G6: Bảo quản trong ngăn mát, tránh để dập lá. | H6: 300g | J6: Giàu sắt, vitamin C, E và chất chống oxy hóa... Lá tím đỏ, vị dịu ngọt. | K6: Ngọt | L6: Tươi | M6: Nấu canh | N6: Nội địa | O6: Origin|Standard|Preservation|Weight|Attributes|Seasonality heuristic | P6: Origin; Season window; Standard/cert; Preservation guidance; Flavor/Texture/Usage | Q6: Trung bình | R6: B4 | S6: Rau lá, rau thơm và nhóm thân/mầm; thường có quanh năm nhưng peak và vùng trồng khác nhau. | T6: Pending | V6: =COUNTIF('Seasonality Evidence'!B:B,A6) | W6: =COUNTIF('Seasonality Evidence'!B:B,A6) | X6: =COUNTIF('Research Evidence'!B:B,A6)
A7: 6 | B7: Rau ăn hoa / thân / mầm | C7: Bông cải xanh | D7: VEG-BCX-006 | E7: Lâm Đồng, Việt Nam | F7: GlobalGAP | G7: Đặt trong hộp kín, ngăn mát 3–5°C, giữ được 3–4 ngày. | H7: 500g | I7: 5 | J7: Giàu vitamin C, K, A và chất xơ... Bông chắc, xanh sẫm, giòn ngọt. | K7: Ngọt | L7: Giòn | M7: Salad / ăn sống | N7: Nội địa | O7: Origin|Standard|Preservation|Weight|Attributes|Seasonality heuristic | P7: Origin; Season window; Standard/cert; Preservation guidance; Flavor/Texture/Usage | Q7: Trung bình | R7: B4 | S7: Rau lá, rau thơm và nhóm thân/mầm; thường có quanh năm nhưng peak và vùng trồng khác nhau. | T7: Pending | V7: =COUNTIF('Seasonality Evidence'!B:B,A7) | W7: =COUNTIF('Seasonality Evidence'!B:B,A7) | X7: =COUNTIF('Research Evidence'!B:B,A7)
A8: 7 | B8: Rau ăn hoa / thân / mầm | C8: Súp lơ trắng | D8: VEG-SL-007 | E8: Bình Thuận, Việt Nam | F8: VietGAP | G8: Bảo quản trong túi giấy hoặc túi thoáng khí. | H8: 600g | J8: Giàu vitamin C, K, folate và chất xơ... Bông trắng đều, vị ngọt dịu. | K8: Ngọt dịu | L8: Tươi | M8: Xào / nấu canh | N8: Nội địa | O8: Origin|Standard|Preservation|Weight|Attributes|Seasonality heuristic | P8: Origin; Season window; Standard/cert; Preservation guidance; Flavor/Texture/Usage | Q8: Trung bình | R8: B4 | S8: Rau lá, rau thơm và nhóm thân/mầm; thường có quanh năm nhưng peak và vùng trồng khác nhau. | T8: Pending | V8: =COUNTIF('Seasonality Evidence'!B:B,A8) | W8: =COUNTIF('Seasonality Evidence'!B:B,A8) | X8: =COUNTIF('Research Evidence'!B:B,A8)
A9: 8 | B9: Rau ăn hoa / thân / mầm | C9: Măng tây xanh | D9: VEG-MT-008 | E9: Ninh Thuận, Việt Nam | F9: GlobalGAP | G9: Giữ trong khăn ẩm, đặt ngăn mát để giữ độ tươi. | H9: 250g | J9: Giàu vitamin A, C, E và folate... Non mướt, giòn, thơm nhẹ. | K9: Tự nhiên | L9: Giòn | M9: Xào | N9: Nội địa | O9: Origin|Standard|Preservation|Weight|Attributes|Seasonality heuristic | P9: Origin; Season window; Standard/cert; Preservation guidance; Flavor/Texture/Usage | Q9: Trung bình | R9: B4 | S9: Rau lá, rau thơm và nhóm thân/mầm; thường có quanh năm nhưng peak và vùng trồng khác nhau. | T9: Pending | V9: =COUNTIF('Seasonality Evidence'!B:B,A9) | W9: =COUNTIF('Seasonality Evidence'!B:B,A9) | X9: =COUNTIF('Research Evidence'!B:B,A9)
A10: 9 | B10: Rau ăn hoa / thân / mầm | C10: Rau mầm hướng dương | D10: VEG-RMH-009 | E10: Cần Thơ, Việt Nam | F10: VietGAP | G10: Dùng ngay trong ngày, bảo quản ngăn mát. | H10: 150g | J10: Giàu vitamin E, C, enzyme tự nhiên và kẽm... Tươi giòn, dễ ăn. | K10: Ngọt | L10: Giòn | M10: Salad / ăn sống | N10: Nội địa | O10: Origin|Standard|Preservation|Weight|Attributes|Seasonality heuristic | P10: Origin; Season window; Standard/cert; Preservation guidance; Flavor/Texture/Usage | Q10: Trung bình | R10: B4 | S10: Rau lá, rau thơm và nhóm thân/mầm; thường có quanh năm nhưng peak và vùng trồng khác nhau. | T10: Pending | V10: =COUNTIF('Seasonality Evidence'!B:B,A10) | W10: =COUNTIF('Seasonality Evidence'!B:B,A10) | X10: =COUNTIF('Research Evidence'!B:B,A10)
A11: 10 | B11: Rau ăn quả | C11: Cà chua bi | D11: VEG-CTB-010 | E11: Đà Lạt, Việt Nam | F11: VietGAP | G11: Để nơi thoáng mát, tránh nhiệt độ cao. | H11: 300g | J11: Giàu vitamin A, C, lycopene và kali... Quả mọng, vị ngọt thanh. | K11: Ngọt thanh | L11: Tươi | M11: Salad / ăn sống | N11: Nội địa | O11: Origin|Standard|Preservation|Weight|Attributes|Seasonality heuristic | P11: Origin; Season window; Standard/cert; Preservation guidance; Flavor/Texture/Usage | Q11: Trung bình | R11: B5 | S11: Rau ăn quả, củ/rễ, nấm và nhóm còn lại; kiểm tra seasonality/cultivation theo vùng hoặc mô hình trồng. | T11: Pending | V11: =COUNTIF('Seasonality Evidence'!B:B,A11) | W11: =COUNTIF('Seasonality Evidence'!B:B,A11) | X11: =COUNTIF('Research Evidence'!B:B,A11)
A12: 11 | B12: Rau ăn quả | C12: Dưa leo mini | D12: VEG-DLM-011 | E12: Bến Tre, Việt Nam | F12: OCOP 3 sao | G12: Giữ nơi khô ráo, có thể để ngăn mát nếu chưa dùng. | H12: 400g | J12: Giàu vitamin C, K và nước tự nhiên... Xanh tươi, giòn mát. | K12: Tự nhiên | L12: Giòn | M12: Salad / ăn sống | N12: Nội địa | O12: Origin|Standard|Preservation|Weight|Attributes|Seasonality heuristic | P12: Origin; Season window; Standard/cert; Preservation guidance; Flavor/Texture/Usage | Q12: Trung bình | R12: B5 | S12: Rau ăn quả, củ/rễ, nấm và nhóm còn lại; kiểm tra seasonality/cultivation theo vùng hoặc mô hình trồng. | T12: Pending | V12: =COUNTIF('Seasonality Evidence'!B:B,A12) | W12: =COUNTIF('Seasonality Evidence'!B:B,A12) | X12: =COUNTIF('Research Evidence'!B:B,A12)
A13: 12 | B13: Rau ăn quả | C13: Bí đỏ | D13: VEG-BD-012 | E13: Bình Dương, Việt Nam | F13: VietGAP | G13: Bảo quản nơi khô mát, có thể để 5–7 ngày. | H13: 1kg | J13: Giàu vitamin A, C, beta-carotene và chất xơ... Dẻo thơm, ngọt nhẹ. | K13: Ngọt nhẹ | L13: Tươi | M13: Nấu canh | N13: Nội địa | O13: Origin|Standard|Preservation|Weight|Attributes|Seasonality heuristic | P13: Origin; Season window; Standard/cert; Preservation guidance; Flavor/Texture/Usage | Q13: Trung bình | R13: B5 | S13: Rau ăn quả, củ/rễ, nấm và nhóm còn lại; kiểm tra seasonality/cultivation theo vùng hoặc mô hình trồng. | T13: Pending | V13: =COUNTIF('Seasonality Evidence'!B:B,A13) | W13: =COUNTIF('Seasonality Evidence'!B:B,A13) | X13: =COUNTIF('Research Evidence'!B:B,A13)
A14: 13 | B14: Củ & rễ | C14: Cà rốt | D14: VEG-CR-013 | E14: Lâm Đồng, Việt Nam | F14: VietGAP | G14: Giữ trong túi lưới hoặc hộp nhựa thoáng khí, ngăn mát. | H14: 500g | J14: Giàu vitamin A, C, K và beta-carotene... Giòn ngọt, tốt cho mắt. | K14: Ngọt | L14: Giòn | M14: Xào | N14: Nội địa | O14: Origin|Standard|Preservation|Weight|Attributes|Seasonality heuristic | P14: Origin; Season window; Standard/cert; Preservation guidance; Flavor/Texture/Usage | Q14: Trung bình | R14: B5 | S14: Rau ăn quả, củ/rễ, nấm và nhóm còn lại; kiểm tra seasonality/cultivation theo vùng hoặc mô hình trồng. | T14: Pending | V14: =COUNTIF('Seasonality Evidence'!B:B,A14) | W14: =COUNTIF('Seasonality Evidence'!B:B,A14) | X14: =COUNTIF('Research Evidence'!B:B,A14)
A15: 14 | B15: Củ & rễ | C15: Khoai tây vàng | D15: VEG-KTV-014 | E15: Đà Lạt, Việt Nam | F15: GlobalGAP | G15: Để nơi thoáng, tránh ánh sáng để không mọc mầm. | H15: 800g | J15: Giàu vitamin C, B6, kali và tinh bột tự nhiên... Ruột vàng, dẻo thơm. | K15: Tự nhiên | L15: Tươi | M15: Nướng | N15: Nội địa | O15: Origin|Standard|Preservation|Weight|Attributes|Seasonality heuristic | P15: Origin; Season window; Standard/cert; Preservation guidance; Flavor/Texture/Usage | Q15: Trung bình | R15: B5 | S15: Rau ăn quả, củ/rễ, nấm và nhóm còn lại; kiểm tra seasonality/cultivation theo vùng hoặc mô hình trồng. | T15: Pending | V15: =COUNTIF('Seasonality Evidence'!B:B,A15) | W15: =COUNTIF('Seasonality Evidence'!B:B,A15) | X15: =COUNTIF('Research Evidence'!B:B,A15)
A16: 15 | B16: Rau lá | C16: Rau cải ngọt | D16: VEG-RCN-015 | E16: Đà Lạt, Việt Nam | F16: VietGAP | G16: Bảo quản ngăn mát, dùng trong 2-3 ngày. | H16: 400g | J16: Giàu vitamin A, C, vị ngọt tự nhiên... Lá xanh mướt, giòn, dễ chế biến. | K16: Ngọt | L16: Giòn | M16: Xào / nấu canh | N16: Nội địa | O16: Origin|Standard|Preservation|Weight|Attributes|Seasonality heuristic | P16: Origin; Season window; Standard/cert; Preservation guidance; Flavor/Texture/Usage | Q16: Trung bình | R16: B4 | S16: Rau lá, rau thơm và nhóm thân/mầm; thường có quanh năm nhưng peak và vùng trồng khác nhau. | T16: Pending | V16: =COUNTIF('Seasonality Evidence'!B:B,A16) | W16: =COUNTIF('Seasonality Evidence'!B:B,A16) | X16: =COUNTIF('Research Evidence'!B:B,A16)
A17: 16 | B17: Rau lá | C17: Cải ngồng | D17: VEG-CN-016 | E17: Lâm Đồng, Việt Nam | F17: GlobalGAP | G17: Để nơi khô thoáng, tránh nắng. | H17: 500g | J17: Giàu vitamin K, C, canxi... Lá xanh đậm, giòn ngọt, bổ dưỡng. | K17: Ngọt | L17: Giòn | M17: Xào / nấu canh | N17: Nội địa | O17: Origin|Standard|Preservation|Weight|Attributes|Seasonality heuristic | P17: Origin; Season window; Standard/cert; Preservation guidance; Flavor/Texture/Usage | Q17: Trung bình | R17: B4 | S17: Rau lá, rau thơm và nhóm thân/mầm; thường có quanh năm nhưng peak và vùng trồng khác nhau. | T17: Pending | V17: =COUNTIF('Seasonality Evidence'!B:B,A17) | W17: =COUNTIF('Seasonality Evidence'!B:B,A17) | X17: =COUNTIF('Research Evidence'!B:B,A17)
A18: 17 | B18: Rau lá | C18: Rau diếp cá | D18: VEG-RDC-017 | E18: Đồng Nai, Việt Nam | F18: OCOP 3 sao | G18: Giữ nơi mát, dùng trong 2 ngày. | H18: 300g | J18: Giàu khoáng chất, vitamin... Vị đặc trưng, tốt cho sức khỏe. | K18: Tự nhiên | L18: Tươi | M18: Salad / ăn sống | N18: Nội địa | O18: Origin|Standard|Preservation|Weight|Attributes|Seasonality heuristic | P18: Origin; Season window; Standard/cert; Preservation guidance; Flavor/Texture/Usage | Q18: Trung bình | R18: B4 | S18: Rau lá, rau thơm và nhóm thân/mầm; thường có quanh năm nhưng peak và vùng trồng khác nhau. | T18: Pending | V18: =COUNTIF('Seasonality Evidence'!B:B,A18) | W18: =COUNTIF('Seasonality Evidence'!B:B,A18) | X18: =COUNTIF('Research Evidence'!B:B,A18)
A19: 18 | B19: Rau lá | C19: Rau má | D19: VEG-RM-018 | E19: Tiền Giang, Việt Nam | F19: VietGAP | G19: Ngăn mát tủ lạnh, dùng trong 3 ngày. | H19: 250g | J19: Giàu vitamin B, giải nhiệt... Lá non xanh, mát gan thanh nhiệt. | K19: Thanh | L19: Tươi | M19: Salad / ăn sống | N19: Nội địa | O19: Origin|Standard|Preservation|Weight|Attributes|Seasonality heuristic | P19: Origin; Season window; Standard/cert; Preservation guidance; Flavor/Texture/Usage | Q19: Trung bình | R19: B4 | S19: Rau lá, rau thơm và nhóm thân/mầm; thường có quanh năm nhưng peak và vùng trồng khác nhau. | T19: Pending | V19: =COUNTIF('Seasonality Evidence'!B:B,A19) | W19: =COUNTIF('Seasonality Evidence'!B:B,A19) | X19: =COUNTIF('Research Evidence'!B:B,A19)
... A37: 36 | B37: Rau ăn hoa / thân / mầm | C37: Măng tre tươi | D37: VEG-MTT-036 | E37: Nghệ An, Việt Nam | F37: OCOP 4 sao | G37: Ngâm nước, đặt ngăn mát. | H37: 600g | J37: Giàu chất xơ, protein thực vật... Măng non giòn, ngọt thanh. | K37: Ngọt thanh | L37: Giòn | M37: Xào / nấu canh | N37: Nội địa | O37: Origin|Standard|Preservation|Weight|Attributes|Seasonality heuristic | P37: Origin; Season window; Standard/cert; Preservation guidance; Flavor/Texture/Usage | Q37: Trung bình | R37: B4 | S37: Rau lá, rau thơm và nhóm thân/mầm; thường có quanh năm nhưng peak và vùng trồng khác nhau. | T37: Pending | V37: =COUNTIF('Seasonality Evidence'!B:B,A37) | W37: =COUNTIF('Seasonality Evidence'!B:B,A37) | X37: =COUNTIF('Research Evidence'!B:B,A37)
A38: 37 | B38: Rau ăn hoa / thân / mầm | C38: Bắp cải tím | D38: VEG-BCT-037 | E38: Đà Lạt, Việt Nam | F38: VietGAP | G38: Bảo quản ngăn mát 1-2 tuần. | H38: 800g | I38: 7 | J38: Giàu anthocyanin, vitamin C, K... Màu tím đẹp, giòn ngọt. | K38: Ngọt | L38: Giòn | M38: Salad / ăn sống | N38: Nội địa | O38: Origin|Standard|Preservation|Weight|Attributes|Seasonality heuristic | P38: Origin; Season window; Standard/cert; Preservation guidance; Flavor/Texture/Usage | Q38: Trung bình | R38: B4 | S38: Rau lá, rau thơm và nhóm thân/mầm; thường có quanh năm nhưng peak và vùng trồng khác nhau. | T38: Pending | V38: =COUNTIF('Seasonality Evidence'!B:B,A38) | W38: =COUNTIF('Seasonality Evidence'!B:B,A38) | X38: =COUNTIF('Research Evidence'!B:B,A38)
A39: 38 | B39: Rau ăn hoa / thân / mầm | C39: Cải Brussels sprouts | D39: VEG-CBS-038 | E39: Lâm Đồng, Việt Nam | F39: GlobalGAP | G39: Ngăn mát, dùng trong 1 tuần. | H39: 350g | I39: 7 | J39: Giàu vitamin C, K, chất xơ... Búp nhỏ xanh, vị đậm đà. | K39: Tự nhiên | L39: Tươi | M39: Xào | N39: Nội địa | O39: Origin|Standard|Preservation|Weight|Attributes|Seasonality heuristic | P39: Origin; Season window; Standard/cert; Preservation guidance; Flavor/Texture/Usage | Q39: Trung bình | R39: B4 | S39: Rau lá, rau thơm và nhóm thân/mầm; thường có quanh năm nhưng peak và vùng trồng khác nhau. | T39: Pending | V39: =COUNTIF('Seasonality Evidence'!B:B,A39) | W39: =COUNTIF('Seasonality Evidence'!B:B,A39) | X39: =COUNTIF('Research Evidence'!B:B,A39)
A40: 39 | B40: Rau ăn hoa / thân / mầm | C40: Rau mầm alfalfa | D40: VEG-RMA-039 | E40: TP.HCM, Việt Nam | F40: VietGAP | G40: Dùng ngay trong ngày. | H40: 150g | J40: Giàu protein, vitamin K, enzyme... Mầm tươi giòn, dễ tiêu hóa. | K40: Tự nhiên | L40: Giòn | M40: Salad / ăn sống | N40: Nội địa | O40: Origin|Standard|Preservation|Weight|Attributes|Seasonality heuristic | P40: Origin; Season window; Standard/cert; Preservation guidance; Flavor/Texture/Usage | Q40: Trung bình | R40: B4 | S40: Rau lá, rau thơm và nhóm thân/mầm; thường có quanh năm nhưng peak và vùng trồng khác nhau. | T40: Pending | V40: =COUNTIF('Seasonality Evidence'!B:B,A40) | W40: =COUNTIF('Seasonality Evidence'!B:B,A40) | X40: =COUNTIF('Research Evidence'!B:B,A40)
A41: 40 | B41: Rau ăn quả | C41: Ớt hiểm | D41: VEG-OH-040 | E41: Bình Dương, Việt Nam | F41: VietGAP | G41: Nơi khô mát 5-7 ngày. | H41: 250g | J41: Giàu vitamin C, capsaicin... Quả nhỏ xanh/đỏ, cay nồng. | K41: Cay | L41: Tươi | M41: Đa dụng | N41: Nội địa | O41: Origin|Standard|Preservation|Weight|Attributes|Seasonality heuristic | P41: Origin; Season window; Standard/cert; Preservation guidance; Flavor/Texture/Usage | Q41: Trung bình | R41: B5 | S41: Rau ăn quả, củ/rễ, nấm và nhóm còn lại; kiểm tra seasonality/cultivation theo vùng hoặc mô hình trồng. | T41: Pending | V41: =COUNTIF('Seasonality Evidence'!B:B,A41) | W41: =COUNTIF('Seasonality Evidence'!B:B,A41) | X41: =COUNTIF('Research Evidence'!B:B,A41)
A42: 41 | B42: Rau ăn quả | C42: Bầu xanh | D42: VEG-BX-041 | E42: Long An, Việt Nam | F42: VietGAP | G42: Nơi khô thoáng 5-7 ngày. | H42: 1.5kg | I42: 7 | J42: Giàu nước, vitamin B, C... Quả xanh tươi, vị ngọt mát. | K42: Ngọt | L42: Tươi | M42: Xào / nấu canh | N42: Nội địa | O42: Origin|Standard|Preservation|Weight|Attributes|Seasonality heuristic | P42: Origin; Season window; Standard/cert; Preservation guidance; Flavor/Texture/Usage | Q42: Trung bình | R42: B5 | S42: Rau ăn quả, củ/rễ, nấm và nhóm còn lại; kiểm tra seasonality/cultivation theo vùng hoặc mô hình trồng. | T42: Pending | V42: =COUNTIF('Seasonality Evidence'!B:B,A42) | W42: =COUNTIF('Seasonality Evidence'!B:B,A42) | X42: =COUNTIF('Research Evidence'!B:B,A42)
A43: 42 | B43: Rau ăn quả | C43: Mướp hương | D43: VEG-MH-042 | E43: Tiền Giang, Việt Nam | F43: VietGAP | G43: Nơi khô mát 4-5 ngày. | H43: 600g | J43: Giàu vitamin A, C, chất xơ... Quả xanh dài, giòn ngọt. | K43: Ngọt | L43: Giòn | M43: Xào / nấu canh | N43: Nội địa | O43: Origin|Standard|Preservation|Weight|Attributes|Seasonality heuristic | P43: Origin; Season window; Standard/cert; Preservation guidance; Flavor/Texture/Usage | Q43: Trung bình | R43: B5 | S43: Rau ăn quả, củ/rễ, nấm và nhóm còn lại; kiểm tra seasonality/cultivation theo vùng hoặc mô hình trồng. | T43: Pending | V43: =COUNTIF('Seasonality Evidence'!B:B,A43) | W43: =COUNTIF('Seasonality Evidence'!B:B,A43) | X43: =COUNTIF('Research Evidence'!B:B,A43)
A44: 43 | B44: Rau ăn quả | C44: Dưa chuột baby | D44: VEG-DCB-043 | E44: Lâm Đồng, Việt Nam | F44: GlobalGAP | G44: Ngăn mát 3-4 ngày. | H44: 300g | J44: Giàu nước, vitamin K... Quả nhỏ giòn, ngọt thanh. | K44: Ngọt thanh | L44: Giòn | M44: Salad / ăn sống | N44: Nội địa | O44: Origin|Standard|Preservation|Weight|Attributes|Seasonality heuristic | P44: Origin; Season window; Standard/cert; Preservation guidance; Flavor/Texture/Usage | Q44: Trung bình | R44: B5 | S44: Rau ăn quả, củ/rễ, nấm và nhóm còn lại; kiểm tra seasonality/cultivation theo vùng hoặc mô hình trồng. | T44: Pending | V44: =COUNTIF('Seasonality Evidence'!B:B,A44) | W44: =COUNTIF('Seasonality Evidence'!B:B,A44) | X44: =COUNTIF('Research Evidence'!B:B,A44)
A45: 44 | B45: Rau ăn quả | C45: Đậu bắp | D45: VEG-DB-044 | E45: Đà Lạt, Việt Nam | F45: VietGAP | G45: Ngăn mát 4-5 ngày. | H45: 400g | J45: Giàu chất xơ, folate... Quả xanh giòn, vị ngọt nhẹ. | K45: Ngọt nhẹ | L45: Giòn | M45: Xào / nấu canh | N45: Nội địa | O45: Origin|Standard|Preservation|Weight|Attributes|Seasonality heuristic | P45: Origin; Season window; Standard/cert; Preservation guidance; Flavor/Texture/Usage | Q45: Trung bình | R45: B5 | S45: Rau ăn quả, củ/rễ, nấm và nhóm còn lại; kiểm tra seasonality/cultivation theo vùng hoặc mô hình trồng. | T45: Pending | V45: =COUNTIF('Seasonality Evidence'!B:B,A45) | W45: =COUNTIF('Seasonality Evidence'!B:B,A45) | X45: =COUNTIF('Research Evidence'!B:B,A45)
A46: 45 | B46: Củ & rễ | C46: Củ cải trắng | D46: VEG-CCT-045 | E46: Đà Lạt, Việt Nam | F46: VietGAP | G46: Nơi khô mát 1-2 tuần. | H46: 800g | J46: Giàu vitamin C, chất xơ... Củ trắng giòn, vị ngọt thanh. | K46: Ngọt thanh | L46: Giòn | M46: Nấu canh | N46: Nội địa | O46: Origin|Standard|Preservation|Weight|Attributes|Seasonality heuristic | P46: Origin; Season window; Standard/cert; Preservation guidance; Flavor/Texture/Usage | Q46: Trung bình | R46: B5 | S46: Rau ăn quả, củ/rễ, nấm và nhóm còn lại; kiểm tra seasonality/cultivation theo vùng hoặc mô hình trồng. | T46: Pending | V46: =COUNTIF('Seasonality Evidence'!B:B,A46) | W46: =COUNTIF('Seasonality Evidence'!B:B,A46) | X46: =COUNTIF('Research Evidence'!B:B,A46)
A47: 46 | B47: Củ & rễ | C47: Khoai lang Nhật | D47: VEG-KLN-046 | E47: Nhật Bản (trồng VN) | F47: GlobalGAP | G47: Nơi khô thoáng 2-3 tuần. | H47: 700g | J47: Giàu beta-carotene, chất xơ... Củ vàng cam, ngọt bùi. | K47: Ngọt | L47: Tươi | M47: Nướng | N47: Nước ngoài / cần kiểm tra | O47: Origin|Standard|Preservation|Weight|Attributes|Seasonality heuristic | P47: Origin; Season window; Standard/cert; Preservation guidance; Flavor/Texture/Usage | Q47: Cao | R47: B2 | S47: Hàng nhập khẩu/hybrid origin/non-fruit cần nguồn gốc rất chặt và note rõ mức chắc chắn. | T47: Partially verified - batch 2 | U47: Bắc Giang: khoai lang Nhật trồng 2 vụ/năm, vụ Xuân thu đầu tháng 5 âm lịch và vụ Đông thu tháng 12 âm lịch; Tây Ninh có mô hình khoai lang tím Nhật vụ Đông Xuân. | V47: 2 | W47: 2 | X47: 1 | Y47: Vietnam; Japan variety/origin label needs supplier confirmation | Z47: Bắc Giang; Tây Ninh | AA47: Domestic-grown / foreign variety label | AB47: GlobalGAP chưa kiểm chứng từ nguồn công khai | AC47: Nơi khô thoáng; cần xác nhận theo quy cách đóng gói nội bộ | AD47: Ngọt | AE47: Bở/dẻo tùy giống; nguồn không xác nhận SKU | AF47: Nướng, luộc, hấp | AG47: https://khuyennongvn.gov.vn/chuong-trinh-nganh-nong-nghiep/tai-co-cau-nganh-nong-nghiep/bac-giang-trong-khoai-thu-nhap-tren-120-150-trieu-donghavu-15779.html | AH47: https://khuyennongvn.gov.vn/chuong-trinh-nganh-nong-nghiep/tai-co-cau-nganh-nong-nghiep/khoai-lang-tim-nhat-cay-trong-tiem-nang-cho-nong-dan-tay-ninh-31095.html | AI47: 2026-04-24 21:12:38 ICT | AJ47: Chưa có nguồn công khai xác nhận GlobalGAP, vùng cung ứng SKU hiện tại hoặc nhãn 'Nhật Bản (trồng VN)'. | AK47: Nên đối chiếu chứng nhận/COA/nhà cung cấp trước khi nhập DB chính thức.
A48: 47 | B48: Củ & rễ | C48: Sắn lùn | D48: VEG-SL-047 | E48: Tây Nguyên, Việt Nam | F48: OCOP 3 sao | G48: Nơi khô thoáng 1 tuần. | H48: 1kg | J48: Giàu tinh bột, vitamin B... Củ trắng, bùi dẻo. | K48: Bùi | L48: Tươi | M48: Đa dụng | N48: Nội địa | O48: Origin|Standard|Preservation|Weight|Attributes|Seasonality heuristic | P48: Origin; Season window; Standard/cert; Preservation guidance; Flavor/Texture/Usage | Q48: Trung bình | R48: B5 | S48: Rau ăn quả, củ/rễ, nấm và nhóm còn lại; kiểm tra seasonality/cultivation theo vùng hoặc mô hình trồng. | T48: Pending | V48: =COUNTIF('Seasonality Evidence'!B:B,A48) | W48: =COUNTIF('Seasonality Evidence'!B:B,A48) | X48: =COUNTIF('Research Evidence'!B:B,A48)
A49: 48 | B49: Củ & rễ | C49: Gừng tươi | D49: VEG-GT-048 | E49: Lâm Đồng, Việt Nam | F49: VietGAP | G49: Nơi khô mát 2-3 tuần. | H49: 500g | J49: Giàu gingerol, chất chống viêm... Củ vàng, cay thơm. | K49: Cay | L49: Tươi | M49: Đa dụng | N49: Nội địa | O49: Origin|Standard|Preservation|Weight|Attributes|Seasonality heuristic | P49: Origin; Season window; Standard/cert; Preservation guidance; Flavor/Texture/Usage | Q49: Trung bình | R49: B5 | S49: Rau ăn quả, củ/rễ, nấm và nhóm còn lại; kiểm tra seasonality/cultivation theo vùng hoặc mô hình trồng. | T49: Pending | V49: =COUNTIF('Seasonality Evidence'!B:B,A49) | W49: =COUNTIF('Seasonality Evidence'!B:B,A49) | X49: =COUNTIF('Research Evidence'!B:B,A49)
A50: 49 | B50: Củ & rễ | C50: Hành tây tím | D50: VEG-HTT-049 | E50: Đà Lạt, Việt Nam | F50: GlobalGAP | G50: Nơi khô thoáng 3-4 tuần. | H50: 600g | J50: Giàu quercetin, vitamin C... Củ tím đẹp, vị ngọt nhẹ. | K50: Ngọt nhẹ | L50: Tươi | M50: Salad / ăn sống | N50: Nội địa | O50: Origin|Standard|Preservation|Weight|Attributes|Seasonality heuristic | P50: Origin; Season window; Standard/cert; Preservation guidance; Flavor/Texture/Usage | Q50: Trung bình | R50: B5 | S50: Rau ăn quả, củ/rễ, nấm và nhóm còn lại; kiểm tra seasonality/cultivation theo vùng hoặc mô hình trồng. | T50: Pending | V50: =COUNTIF('Seasonality Evidence'!B:B,A50) | W50: =COUNTIF('Seasonality Evidence'!B:B,A50) | X50: =COUNTIF('Research Evidence'!B:B,A50)
A51: 50 | B51: Nấm | C51: Nấm kim châm | D51: VEG-NKC-050 | E51: Lâm Đồng, Việt Nam | F51: VietGAP | G51: Ngăn mát 4-5 ngày. | H51: 300g | J51: Giàu đạm, vitamin D... Nấm trắng dài, giòn ngọt. | K51: Ngọt | L51: Giòn | M51: Xào / nấu canh | N51: Nội địa | O51: Origin|Standard|Preservation|Weight|Attributes|Seasonality heuristic | P51: Origin; Season window; Standard/cert; Preservation guidance; Flavor/Texture/Usage | Q51: Trung bình | R51: B5 | S51: Rau ăn quả, củ/rễ, nấm và nhóm còn lại; kiểm tra seasonality/cultivation theo vùng hoặc mô hình trồng. | T51: Pending | V51: =COUNTIF('Seasonality Evidence'!B:B,A51) | W51: =COUNTIF('Seasonality Evidence'!B:B,A51) | X51: =COUNTIF('Research Evidence'!B:B,A51)
A52: 51 | B52: Nấm | C52: Nấm bào ngư | D52: VEG-NBN-051 | E52: Đà Lạt, Việt Nam | F52: GlobalGAP | G52: Ngăn mát 5-6 ngày. | H52: 400g | J52: Giàu protein, vitamin B... Nấm tai lớn, thơm ngon. | K52: Tự nhiên | L52: Tươi | M52: Xào / nấu canh | N52: Nội địa | O52: Origin|Standard|Preservation|Weight|Attributes|Seasonality heuristic | P52: Origin; Season window; Standard/cert; Preservation guidance; Flavor/Texture/Usage | Q52: Trung bình | R52: B5 | S52: Rau ăn quả, củ/rễ, nấm và nhóm còn lại; kiểm tra seasonality/cultivation theo vùng hoặc mô hình trồng. | T52: Pending | V52: =COUNTIF('Seasonality Evidence'!B:B,A52) | W52: =COUNTIF('Seasonality Evidence'!B:B,A52) | X52: =COUNTIF('Research Evidence'!B:B,A52)
A53: 52 | B53: Nấm | C53: Nấm hương khô | D53: VEG-NHK-052 | E53: Trung Quốc | F53: Organic | G53: Nơi khô ráo, tránh ẩm. | H53: 200g | J53: Giàu umami, vitamin D... Nấm khô thơm đậm, bổ dưỡng. | K53: Tự nhiên | L53: Tươi | M53: Xào / nấu canh | N53: Nước ngoài / cần kiểm tra | O53: Origin|Standard|Preservation|Weight|Attributes|Seasonality heuristic | P53: Origin; Season window; Standard/cert; Preservation guidance; Flavor/Texture/Usage | Q53: Cao | R53: B2 | S53: Hàng nhập khẩu/hybrid origin/non-fruit cần nguồn gốc rất chặt và note rõ mức chắc chắn. | T53: Partially verified - batch 2 | U53: Nấm hương khô là sản phẩm chế biến/khô; mùa vụ bán lẻ không nên suy ra bằng lịch tươi nếu chưa có dữ liệu theo lô. Trung Quốc có sản xuất và xuất khẩu nấm hương khô. | V53: 1 | W53: 1 | X53: 2 | Y53: China | Z53: China; Hubei/Suizhou context for processed shiitake | AA53: Imported | AB53: Organic chưa kiểm chứng từ nguồn công khai | AC53: Nơi khô ráo, tránh ẩm; cần giữ kín bao bì sau mở | AD53: Umami, mùi nấm đậm | AE53: Khô; mềm lại sau ngâm | AF53: Xào, nấu canh, hầm | AG53: https://fao.org/docrep/fao/005/AB598E/AB598E00.pdf | AH53: https://en.people.cn/n3/2025/0930/c98649-20373212.html | AI53: 2026-04-24 21:12:38 ICT | AJ53: Chưa xác nhận chứng nhận Organic, tỉnh sản xuất, nhà xuất khẩu và mùa vụ cụ thể của SKU. | AK53: Cần ưu tiên kiểm chứng bằng chứng từ nhập khẩu/nhãn sản phẩm.
A54: 53 | B54: Nấm | C54: Nấm linh chi đỏ | D54: VEG-NLC-053 | E54: Hàn Quốc (trồng VN) | F54: Dược liệu | G54: Nơi khô ráo, thoáng mát. | H54: 100g | J54: Dược liệu quý, giàu polysaccharide... Nấm đỏ thẫm, bổ dưỡng. | K54: Tự nhiên | L54: Tươi | M54: Nấu canh | N54: Nước ngoài / cần kiểm tra | O54: Origin|Standard|Preservation|Weight|Attributes|Seasonality heuristic | P54: Origin; Season window; Standard/cert; Preservation guidance; Flavor/Texture/Usage | Q54: Cao | R54: B2 | S54: Hàng nhập khẩu/hybrid origin/non-fruit cần nguồn gốc rất chặt và note rõ mức chắc chắn. | T54: Partially verified - batch 2 | U54: Nấm linh chi đỏ trồng theo chu kỳ nuôi trồng: lứa đầu khoảng 3 tháng, có thể thu nhiều lứa cách nhau khoảng 70-80 ngày; không nên gán mùa tự nhiên cố định. | V54: 1 | W54: 1 | X54: 1 | Y54: Vietnam cultivation verified; Korea origin label unverified | Z54: Hòa Bình; Lâm Đồng context cần kiểm chứng thêm nếu SKU ghi Đà Lạt | AA54: Domestic-grown / foreign-origin label needs supplier confirmation | AB54: Dược liệu chưa kiểm chứng bằng tiêu chuẩn cụ thể | AC54: Dạng khô nên để nơi khô ráo, thoáng mát; nguồn ghi sấy 40-45 độ C sau thu hái | AD54: Đắng nhẹ/đặc trưng dược liệu | AE54: Khô, cứng; dùng thái lát/hãm/nấu | AF54: Pha trà, sắc/nấu nước; không nên ghi nấu canh nếu chưa xác nhận mục đích bán | AG54: https://khuyennongvn.gov.vn/chuong-trinh-nganh-nong-nghiep/tai-co-cau-nganh-nong-nghiep/hoa-binh-trong-nam-linh-chi-tren-gia-the-go-keo-tuoi--mo-hinh-kinh-te-hieu-qua-21892.html | AI54: 2026-04-24 21:12:38 ICT | AJ54: Chưa xác nhận giống Hàn Quốc, tiêu chuẩn dược liệu và vùng cung ứng thật của SKU. | AK54: Nên kiểm tra nhãn/COA vì đây là nhóm dược liệu.
A55: 54 | B55: Nấm | C55: Nấm rơm tươi | D55: VEG-NRT-054 | E55: Đồng Tháp, Việt Nam | F55: VietGAP | G55: Ngăn mát 2-3 ngày. | H55: 300g | J55: Giàu protein, vitamin B... Nấm tròn trắng, mềm ngọt. | K55: Ngọt | L55: Mềm | M55: Xào / nấu canh | N55: Nội địa | O55: Origin|Standard|Preservation|Weight|Attributes|Seasonality heuristic | P55: Origin; Season window; Standard/cert; Preservation guidance; Flavor/Texture/Usage | Q55: Trung bình | R55: B5 | S55: Rau ăn quả, củ/rễ, nấm và nhóm còn lại; kiểm tra seasonality/cultivation theo vùng hoặc mô hình trồng. | T55: Pending | V55: =COUNTIF('Seasonality Evidence'!B:B,A55) | W55: =COUNTIF('Seasonality Evidence'!B:B,A55) | X55: =COUNTIF('Research Evidence'!B:B,A55)
A56: 55 | B56: Rau thơm & gia vị | C56: Hành lá | D56: VEG-HL-055 | E56: Long An, Việt Nam | F56: VietGAP | G56: Ngăn mát 3-4 ngày. | H56: 200g | J56: Giàu vitamin K, folate... Lá xanh thơm, vị cay nhẹ. | K56: Cay | L56: Tươi | M56: Đa dụng | N56: Nội địa | O56: Origin|Standard|Preservation|Weight|Attributes|Seasonality heuristic | P56: Origin; Season window; Standard/cert; Preservation guidance; Flavor/Texture/Usage | Q56: Trung bình | R56: B4 | S56: Rau lá, rau thơm và nhóm thân/mầm; thường có quanh năm nhưng peak và vùng trồng khác nhau. | T56: Pending | V56: =COUNTIF('Seasonality Evidence'!B:B,A56) | W56: =COUNTIF('Seasonality Evidence'!B:B,A56) | X56: =COUNTIF('Research Evidence'!B:B,A56)
A57: 56 | B57: Rau thơm & gia vị | C57: Ngò rí | D57: VEG-NR-056 | E57: Tiền Giang, Việt Nam | F57: VietGAP | G57: Ngăn mát 2-3 ngày. | H57: 150g | J57: Giàu vitamin C, K... Lá xanh, thơm đặc trưng. | K57: Tự nhiên | L57: Tươi | M57: Nấu canh | N57: Nội địa | O57: Origin|Standard|Preservation|Weight|Attributes|Seasonality heuristic | P57: Origin; Season window; Standard/cert; Preservation guidance; Flavor/Texture/Usage | Q57: Trung bình | R57: B4 | S57: Rau lá, rau thơm và nhóm thân/mầm; thường có quanh năm nhưng peak và vùng trồng khác nhau. | T57: Pending | V57: =COUNTIF('Seasonality Evidence'!B:B,A57) | W57: =COUNTIF('Seasonality Evidence'!B:B,A57) | X57: =COUNTIF('Research Evidence'!B:B,A57)
...

Sheet Seasonality Evidence
A1: Batch | B1: ProductID | C1: ProductName | D1: CategoryName | E1: Current Origin | F1: Locality Scope | G1: Locality Name | H1: Season Window Label | I1: Start Month | J1: End Month | K1: Peak Months | L1: Main Harvest Window | M1: Cultivation / Availability Notes | N1: Source Title | O1: Source Publisher | P1: Source URL | Q1: Source Date | R1: Trust Level | S1: Thời gian thu thập | T1: Tôi chưa chắc chắn | U1: Reviewer Notes
A2: B1 | B2: 61 | C2: Táo Fuji Nhật | D2: Trái cây | E2: Nhật Bản | F2: Prefecture | G2: Aomori | H2: Fuji export / eating window | I2: 11 | J2: 1 | K2: 11-12 | L2: Yes | M2: Aomori export season starts in October; Fuji is highlighted in November and controlled storage extends quality beyond New Year. | N2: Fruit and Vegetables: Apples | O2: Japan Food Export Fair / Aomori Apple Council | P2: https://j-fec.com/en/producer/pdf/en/20/ | Q2: 2022 | R2: High | S2: 2026-04-24 14:43:30 ICT | T2: End month is inferred from official storage note rather than an explicit Fuji close date. | U2: Use Aomori as the strongest verified locality currently available for Fuji export fruit.
A3: B1 | B3: 62 | C3: Cam Cara ruột đỏ | D3: Trái cây | E3: Úc | F3: Growing regions | G3: Murray Valley / Riverina / Riverland | H3: Australia navel orange season | I3: 6 | J3: 10 | K3: 6-8 | L3: No | M3: Citrus Australia lists navel oranges in season June-October; Agriculture Victoria describes Cara Cara as an early-to-mid-season navel. | N3: What's in Season | O3: Citrus Australia | P3: https://citrusaustralia.com.au/buying-australian/season/ | R3: High | S3: 2026-04-24 14:43:30 ICT | T3: Cara Cara month range is inferred from the broader navel window because a month-by-month Cara Cara calendar was not found. | U3: Treat this as a provisional Australia-season mapping until a variety-specific official calendar is found.
A4: B1 | B4: 63 | C4: Nho Mỹ không hạt | D4: Trái cây | E4: Mỹ | F4: Region | G4: Coachella Valley, California | H4: Early California table grape season | I4: 5 | J4: 7 | K4: 5-6 | L4: Yes | M4: California table grapes begin in Coachella Valley in May and usually finish in early July. | N4: Grapes From California Merchandising and Training Guide | O4: California Table Grape Commission | P4: https://www.grapesfromcalifornia.com/wp-content/uploads/2023/06/20230605-grapes-from-california-merchandising-and-training-guide-2023.pdf | Q4: 2023-06-05 | R4: High | S4: 2026-04-24 14:43:30 ICT
A5: B1 | B5: 63 | C5: Nho Mỹ không hạt | D5: Trái cây | E5: Mỹ | F5: Region | G5: San Joaquin Valley, California | H5: Main California table grape season | I5: 7 | J5: 12 | K5: 8-10 | L5: Yes | M5: The San Joaquin Valley starts in early July and often continues into December. | N5: Grapes From California Merchandising and Training Guide | O5: California Table Grape Commission | P5: https://www.grapesfromcalifornia.com/wp-content/uploads/2023/06/20230605-grapes-from-california-merchandising-and-training-guide-2023.pdf | Q5: 2023-06-05 | R5: High | S5: 2026-04-24 14:43:30 ICT | U5: California grapes are marketed from May into January.
A6: B1 | B6: 71 | C6: Măng cụt | D6: Trái cây | E6: Thái Lan | F6: Country | G6: Thailand | H6: National availability window | I6: 4 | J6: 12 | K6: 4-8 | L6: Yes | M6: The DOAE commodity page states availability from April to December with peak supply in April-August. | N6: Mangosteen | O6: Department of Agricultural Extension, Thailand | P6: https://www.doae.go.th/en/mangosteen-2/ | R6: High | S6: 2026-04-24 14:43:30 ICT
A7: B1 | B7: 71 | C7: Măng cụt | D7: Trái cây | E7: Thái Lan | F7: Province / locality | G7: Khiriwong, Nakhon Si Thammarat | H7: Southern locality fruit season | I7: 7 | J7: 9 | K7: 7-9 | L7: No | M7: Thailand government tourism content notes fruit season in Khiriwong from July to September, including mangosteen. | N7: Kiriwong Village and Khao Luang Mountain | O7: Government of Thailand | P7: https://www.thailand.go.th/issue-focus-detail/001_02_255 | R7: High | S7: 2026-04-24 14:43:30 ICT | U7: Useful as a locality-specific southern Thailand season window.
A8: B1 | B8: 73 | C8: Lựu đỏ Mỹ | D8: Trái cây | E8: Mỹ | F8: Region | G8: San Joaquin Valley, California | H8: California pomegranate season | I8: 10 | J8: 1 | K8: 10-1 | L8: Yes | M8: California pomegranates are described as being in season from October to January and are grown in the San Joaquin Valley. | N8: Why California | O8: POM Wonderful / California Pomegranate Council | P8: https://pomegranates.org/about/why-california/ | R8: High | S8: 2026-04-24 14:43:30 ICT
A9: B1 | B9: 74 | C9: Dưa lưới Nhật | D9: Trái cây | E9: Nhật Bản | F9: Prefecture | G9: Ibaraki | H9: Ibaraki melon shipping window | I9: 4 | J9: 10 | K9: 5-9 | L9: Yes | M9: Ibaraki melons are shipped from late April to late October; Andes, Quincy and Takami peak from spring to early summer while Earl's melons run from summer to autumn. | N9: Melons | O9: Ibaraki Prefecture | P9: https://exports.pref.ibaraki.jp/en/product/detail?id=714713 | R9: High | S9: 2026-04-24 14:43:30 ICT
A10: B1 | B10: 74 | C10: Dưa lưới Nhật | D10: Trái cây | E10: Nhật Bản | F10: Prefecture | G10: Shizuoka | H10: Greenhouse aroma melon supply | I10: 1 | J10: 12 | K10: Year-round | L10: No | M10: Shizuoka's premium aroma melon is cultivated in greenhouses and described as available throughout the year. | N10: Aroma Melon | O10: Shizuoka Prefecture Food Information Center | P10: https://fujinokuni.shokunomiyako-shizuoka.pref.shizuoka.jp/en/buy-food/1884 | R10: High | S10: 2026-04-24 14:43:30 ICT | T10: Catalog origin is generic Japan, so exact supplied prefecture still needs transactional confirmation. | U10: Good example of locality-specific difference versus open-field/standard shipping calendars.
A11: B1 | B11: 75 | C11: Mận đỏ Mỹ | D11: Trái cây | E11: Mỹ | F11: State | G11: California | H11: California plum season | I11: 5 | J11: 12 | K11: 6-8 | L11: Yes | M11: The California plum fact sheet describes the growing season as May-December with the heaviest volume June-August. | N11: Plums | O11: California Department of Education | P11: https://www.cde.ca.gov/ls/nu/fd/plum.asp | R11: High | S11: 2026-04-24 14:43:30 ICT
A12: B1 | B12: 76 | C12: Lê Nam Phi | D12: Trái cây | E12: Nam Phi | F12: Province / region | G12: Western Cape | H12: South African pear harvest start | I12: 1 | L12: No | M12: Hortgro notes that early pear cultivars are harvested in January; exact end windows vary by cultivar. | N12: Pome Fruit Industry Estimates 2025 Season | O12: Hortgro | P12: https://www.hortgro.co.za/wp-content/uploads/docs/dlm_uploads/2025/01/Pome-fruit-industry-estimates_2025-SEASON_FINAL.pdf | Q12: 2025-01 | R12: High | S12: 2026-04-24 14:43:30 ICT | T12: Generic South African pear timing still needs cultivar-specific end-month confirmation. | U12: Use January as verified harvest start only.
A13: B1 | B13: 77 | C13: Kiwi vàng New Zealand | D13: Trái cây | E13: New Zealand | F13: Country | G13: New Zealand | H13: New Zealand kiwifruit harvest | I13: 3 | J13: 5 | K13: 3-5 | L13: Yes | M13: Zespri states New Zealand kiwifruit is harvested from March through May. | N13: When is Kiwifruit Season? | O13: Zespri | P13: https://www.zespri.com/en-US/blogdetail/when-is-kiwifruit-season | R13: High | S13: 2026-04-24 14:43:30 ICT
A14: B1 | B14: 78 | C14: Dứa MD2 Thái Lan | D14: Trái cây | E14: Thái Lan | F14: Country | G14: Thailand | H14: Thailand pineapple general availability | I14: 1 | J14: 12 | K14: 4-7 | L14: No | M14: Thailand DOAE lists pineapple as available year-round, with peak volume in April-July. | N14: Pineapple | O14: Department of Agricultural Extension, Thailand | P14: https://www.doae.go.th/en/pineapple-2/ | R14: High | S14: 2026-04-24 14:43:30 ICT | T14: The official source is for Thai pineapple generally, not a month-by-month MD2-specific calendar. | U14: Keep the MD2 varietal season flagged as provisional.
A15: B1 | B15: 68 | C15: Chuối già Nam Mỹ | D15: Trái cây | E15: Nam Mỹ | F15: Regional tropical belt | G15: South America (exact country not yet confirmed) | H15: Perennial harvest window | I15: 1 | J15: 12 | K15: Year-round | L15: No | M15: FAO describes bananas and plantains as perennial crops that grow quickly and can be harvested all year round in tropical regions. | N15: The World Banana Economy, 1985-2002 | O15: FAO | P15: https://www.fao.org/3/y5102e/y5102e04.htm | R15: High | S15: 2026-04-24 14:48:34 ICT | T15: Catalog chỉ ghi Nam Mỹ, chưa xác định quốc gia xuất xứ thực tế của lô hàng. | U15: Dùng nguồn FAO để xác nhận đặc tính mùa vụ chung; chưa đủ để chốt vùng trồng cụ thể.
A16: B3 | B16: 64 | C16: Xoài cát Hòa Lộc | D16: Trái cây | E16: Tiền Giang, Việt Nam | F16: District / GI area | G16: Cái Bè, Tiền Giang | H16: Mùa vụ GI truyền thống | I16: 2 | J16: 5 | K16: 3-5 | L16: Yes | M16: Tài liệu chỉ dẫn địa lý của Cục Sở hữu trí tuệ ghi mùa vụ thu hoạch từ tháng 2 đến tháng 5 dương lịch. | N16: Chỉ dẫn địa lý – Di sản thiên nhiên và văn hóa Việt Nam | O16: Cục Sở hữu trí tuệ | P16: https://ipvietnam.gov.vn/documents/20195/811934/Ch%E1%BB%89%2Bd%E1%BA%ABn%2B%C4%91%E1%BB%8Ba%2Bl%C3%BD%2B%E2%80%93%2BDi%2Bs%E1%BA%A3n%2Bthi%C3%AAn%2Bnhi%C3%AAn%2Bv%C4%83n%2Bh%C3%B3a%2BVi%E1%BB%87t%2B%28ti%E1%BA%BFng%2BVi%E1%BB%87t%29.pdf/a56b0cb4-d8bd-475a-be64-bba40329fb9f | R16: High | S16: 2026-04-24 14:48:34 ICT
A17: B3 | B17: 64 | C17: Xoài cát Hòa Lộc | D17: Trái cây | E17: Tiền Giang, Việt Nam | F17: District / GI area | G17: Cái Bè, Tiền Giang | H17: Mùa vụ tăng thêm | I17: 10 | J17: 12 | K17: 10-12 | L17: No | M17: Bộ Công Thương ghi nhận hiện nay người trồng đã tăng thêm mùa vụ từ tháng 10 đến tháng 12 dương lịch. | N17: Xoài cát Hòa Lộc nức lòng giới sành ăn | O17: Bộ Công Thương | P17: https://moit.gov.vn/tu-hao-hang-viet-nam/gioi-thieu-xoai-cat-hoa-loc.html | Q17: 2022-09-08 | R17: High | S17: 2026-04-24 14:48:34 ICT | U17: Đây là mùa vụ mở rộng/rải vụ, không phải cửa sổ GI truyền thống.
A18: B3 | B18: 70 | C18: Thanh long ruột đỏ | D18: Trái cây | E18: Bình Thuận, Việt Nam | F18: Province / GI area | G18: Bình Thuận | H18: Vụ nghịch cuối năm - đầu năm | I18: 10 âm lịch | J18: sau Tết | K18: tháng Chạp - sau Tết | L18: No | M18: Sở NN&PTNT Bình Thuận ghi nhận nông dân bắt đầu chong đèn từ tháng 10 âm lịch và các lứa nghịch vụ thu hoạch từ tháng Chạp trở đi để phục vụ thị trường trước và sau Tết. | N18: Thanh long vào vụ nghịch: [Bài 1] Nâng cao chất lượng đáp ứng thị trường | O18: Sở NN&PTNT Bình Thuận | P18: https://snnptnt.binhthuan.gov.vn/tin-nong-nghiep/thanh-long-vao-vu-nghich-bai-1-nang-cao-chat-luong-dap-ung-thi-truong-867366 | Q18: 2023-12-05 | R18: High | S18: 2026-04-24 14:48:34 ICT | T18: Mốc tháng đang ở dạng âm lịch theo nguồn gốc, không ép đổi sang dương lịch để tránh sai lệch theo từng năm. | U18: Nguồn hiện tại mới xác nhận chắc phần vụ nghịch.
A19: B3 | B19: 65 | C19: Dưa hấu không hạt | D19: Trái cây | E19: Long An, Việt Nam | F19: District | G19: Vĩnh Hưng, Long An | H19: Dưa hấu Tết | I19: 12 | J19: 1 | K19: 12-1 | L19: Yes | M19: Báo Long An ghi nhận nông dân Vĩnh Hưng gieo trồng hơn 250ha dưa hấu phục vụ thị trường Tết, dự kiến thu hoạch vào giữa tháng Chạp. | N19: Vĩnh Hưng: Nông dân gieo trồng hơn 250ha dưa hấu phục vụ thị trường tết | O19: Báo Long An | P19: https://baolongan.vn/vinh-hung-nong-dan-gieo-trong-hon-250ha-dua-hau-phuc-vu-thi-truong-tet-a186458.html | Q19: 2024-12-01 | R19: Medium | S19: 2026-04-24 21:05:08 ICT | T19: Nguồn xác nhận vụ Tết tại Long An nhưng không tách riêng giống không hạt. | U19: Dùng chung cho SKU 65 và 118 đến khi có nguồn riêng cho giống không hạt/mini.
A20: B3 | B20: 66 | C20: Bơ Booth 7 | D20: Trái cây | E20: Đắk Lắk, Việt Nam | F20: Province | G20: Đắk Lắk | H20: Chính vụ và vụ muộn | I20: 4 | J20: 11 | K20: 4-7; 9-11 | L20: Yes | M20: Sở Công Thương Đắk Lắk ghi cây bơ có chính vụ từ tháng 4-7 và vụ muộn từ tháng 9-11. | N20: Bơ Đắk Lắk - Hành trình đến với người tiêu dùng | O20: Sở Công Thương Đắk Lắk | P20: https://socongthuong.daklak.gov.vn/vi/news/hoat-dong-nganh-cong-thuong/bo-dak-lak-hanh-trinh-den-voi-nguoi-tieu-dung-3497.html | R20: High | S20: 2026-04-24 21:05:08 ICT | T20: Nguồn nói bơ Đắk Lắk nói chung, trong đó có Booth 7; chưa tách riêng tuyệt đối lịch Booth 7 theo từng vùng nhỏ.
A21: B3 | B21: 67 | C21: Dâu tây Đà Lạt | D21: Trái cây | E21: Đà Lạt, Việt Nam | F21: City / nearby district | G21: Đà Lạt - Lạc Dương, Lâm Đồng | H21: Chu kỳ thu hoạch vụ nhà kính | I21: Sau 4 tháng xuống giống | J21: khoảng 6 tháng sau đó | K21: Mùa nắng cho sản lượng tốt hơn | L21: No | M21: Nguồn Lâm Đồng ghi giống PS8.07/PS8.10 sau khoảng 4 tháng xuống giống bước vào thu hoạch liên tục đến khoảng 6 tháng sau đó; mùa mưa làm sản lượng giảm mạnh so với mùa nắng. | N21: Khảo nghiệm 2 giống dâu tây mới ở Đà Lạt | O21: Thị trấn Lạc Dương, Lâm Đồng | P21: https://thitranlacduong.lamdong.gov.vn/chi-tiet-tin-tuc/?param=khao-nghiem-2-giong-dau-tay-moi-o-da-lat | R21: High | S21: 2026-04-24 21:05:08 ICT | T21: Dâu tây công nghệ cao có thể trồng/thu quanh năm theo lứa; không nên biến thành tháng cố định nếu không có ngày xuống giống. | U21: Dùng thêm nguồn Khuyến nông Lâm Đồng về mùa mưa làm giảm sản lượng.
A22: B3 | B22: 72 | C22: Mít Thái siêu ngọt | D22: Trái cây | E22: Tiền Giang, Việt Nam | F22: Province / specialized areas | G22: Cái Bè, Cai Lậy, Châu Thành, Tân Phước, TX Cai Lậy | H22: Rải vụ gần như quanh năm | I22: 1 | J22: 12 | K22: Year-round | L22: No | M22: Cổng TTĐT Tiền Giang ghi mít Thái siêu sớm cho thu hoạch rải vụ gần như quanh năm. | N22: Giá mít Thái tăng mạnh, giúp nông dân ổn định cuộc sống trong tình hình dịch bệnh còn phức tạp | O22: Cổng thông tin điện tử tỉnh Tiền Giang | P22: https://tiengiang.gov.vn/chi-tiet-tin?%2Fgia-mit-thai-tang-manh-giup-nong-dan-on-inh-cuoc-song-trong-tinh-hinh-dich-benh-con-phuc-tap%2F32403960= | R22: High | S22: 2026-04-24 21:05:08 ICT
A23: B3 | B23: 116 | C23: Chuối già Việt Nam | D23: Trái cây | E23: Tiền Giang, Việt Nam | F23: Domestic tropical crop | G23: Việt Nam / Tiền Giang chưa có nguồn tỉnh đủ chi tiết | H23: Thu hoạch quanh năm - bối cảnh cây chuối | I23: 1 | J23: 12 | K23: 1-4 sản lượng nhiều theo nguồn khuyến nông | L23: No | M23: Nguồn Khuyến nông Việt Nam ghi cây chuối có thể thu hoạch quanh năm, sản lượng nhiều từ tháng 1 đến tháng 4; nguồn không riêng Tiền Giang. | N23: Đồng Tháp: Giá chuối tăng, nông dân vẫn lo | O23: Trung tâm Khuyến nông Quốc gia | P23: https://khuyennongvn.gov.vn/thong-tin-thi-truong/thi-truong-trong-nuoc/dong-thap-gia-chuoi-tang-nong-dan-van-lo-14376.html | R23: Medium | S23: 2026-04-24 21:05:08 ICT | T23: Chưa tìm được nguồn cực mạnh riêng cho chuối già Tiền Giang; tạm dùng nguồn khuyến nông cho cây chuối vùng tương đồng và phải kiểm tiếp.
A24: B3 | B24: 118 | C24: Dưa hấu không hạt mini | D24: Trái cây | E24: Long An, Việt Nam | F24: District | G24: Vĩnh Hưng, Long An | H24: Dưa hấu Tết | I24: 12 | J24: 1 | K24: 12-1 | L24: Yes | M24: Báo Long An ghi nhận nông dân Vĩnh Hưng gieo trồng hơn 250ha dưa hấu phục vụ thị trường Tết, dự kiến thu hoạch vào giữa tháng Chạp. | N24: Vĩnh Hưng: Nông dân gieo trồng hơn 250ha dưa hấu phục vụ thị trường tết | O24: Báo Long An | P24: https://baolongan.vn/vinh-hung-nong-dan-gieo-trong-hon-250ha-dua-hau-phuc-vu-thi-truong-tet-a186458.html | Q24: 2024-12-01 | R24: Medium | S24: 2026-04-24 21:05:08 ICT | T24: Nguồn xác nhận vụ Tết tại Long An nhưng không tách riêng giống không hạt mini.
A25: B3 | B25: 119 | C25: Thanh long ruột trắng | D25: Trái cây | E25: Bình Thuận, Việt Nam | F25: Province / GI area | G25: Bình Thuận | H25: Vụ nghịch cuối năm - đầu năm | I25: 10 âm lịch | J25: sau Tết | K25: tháng Chạp - sau Tết | L25: No | M25: Sở NN&PTNT Bình Thuận ghi nông dân chong đèn từ tháng 10 âm lịch và các lứa nghịch vụ thu hoạch từ tháng Chạp trở đi. | N25: Thanh long vào vụ nghịch: [Bài 1] Nâng cao chất lượng đáp ứng thị trường | O25: Sở NN&PTNT Bình Thuận | P25: https://snnptnt.binhthuan.gov.vn/tin-nong-nghiep/thanh-long-vao-vu-nghich-bai-1-nang-cao-chat-luong-dap-ung-thi-truong-867366 | Q25: 2023-12-05 | R25: High | S25: 2026-04-24 21:05:08 ICT | T25: Nguồn ghi thanh long Bình Thuận nói chung, chưa tách riêng ruột trắng; mốc tháng ở dạng âm lịch nên chưa đổi sang dương lịch.
A26: B3 | B26: 120 | C26: Sầu riêng Ri6 | D26: Trái cây | E26: Đắk Lắk, Việt Nam | F26: Province | G26: Đắk Lắk | H26: Vụ thu hoạch chính ở Đắk Lắk | I26: 8 | J26: 9 | K26: 8-9 | L26: Yes | M26: Khuyến nông Việt Nam ghi sầu riêng Đắk Lắk bắt đầu vào vụ; chính vụ giống Dona tại Krông Pắc từ 27/8 đến đầu tháng 9/2022; Ri6 được nêu cùng nhóm giống chất lượng trong nguồn khác của địa phương. | N26: Đắk Lắk: Sầu riêng được giá, nhưng năng suất năm nay lại thấp | O26: Trung tâm Khuyến nông Quốc gia | P26: https://khuyennongvn.gov.vn/chuong-trinh-nganh-nong-nghiep/tai-co-cau-nganh-nong-nghiep/dak-lak-sau-rieng-duoc-gia-nhung-nang-suat-nam-nay-lai-thap-22052.html | R26: Medium | S26: 2026-04-24 21:05:08 ICT | T26: Nguồn mùa vụ mạnh cho sầu riêng Đắk Lắk nhưng không tách riêng Ri6; cần thêm nguồn cultivar Ri6 tại Đắk Lắk nếu dùng làm claim chính xác tuyệt đối.
A27: B3 | B27: 69 | C27: Đu đủ vàng | D27: Trái cây | E27: Bình Phước, Việt Nam | F27: Province | G27: Bình Phước | H27: Cây ăn trái nhiệt đới gần như quanh năm | I27: 1 | J27: 12 | K27: Year-round | L27: No | M27: Cổng thông tin Bình Phước ghi nhiều chủng loại cây ăn trái của tỉnh hầu như cho thu hoạch quanh năm, trong danh sách có đu đủ. | N27: Bình Phước có nhiều chủng loại cây ăn trái hầu như cho thu hoạch quanh năm | O27: Cổng thông tin điện tử tỉnh Bình Phước | P27: https://binhphuoc.gov.vn/vi/news/Hoat-dong-huyen-thi/phuoc-co-nhieu-chung-loai-cay-an-trai-hau-nhu-cho-thu-hoach-quanh-nam-21193.html | R27: High | S27: 2026-04-24 21:05:08 ICT | T27: Nguồn xác nhận đu đủ trong nhóm cây ăn trái Bình Phước thu hoạch gần như quanh năm, chưa tách riêng giống đu đủ vàng.
A28: B2 | B28: 46 | C28: Khoai lang Nhật | D28: Củ & rễ | E28: Nhật Bản (trồng VN) | F28: Province | G28: Bắc Giang, Việt Nam | H28: 2 vụ/năm: vụ Xuân và vụ Đông | I28: 2 | J28: 12 | K28: Tháng 5 âm lịch; tháng 12 âm lịch | L28: Yes | M28: Khuyến nông Quốc gia ghi khoai lang Nhật tại Bắc Giang trồng được 2 vụ/năm, khoảng 4-5 tháng/vụ; vụ Xuân trồng sau Tết, thu đầu tháng 5 âm lịch; vụ Đông trồng cuối tháng 8-đầu tháng 9, thu tháng 12 âm lịch. | N28: Bắc Giang: Trồng khoai thu nhập trên 120 -150 triệu đồng/ha/vụ | O28: Trung tâm Khuyến nông Quốc gia | P28: https://khuyennongvn.gov.vn/chuong-trinh-nganh-nong-nghiep/tai-co-cau-nganh-nong-nghiep/bac-giang-trong-khoai-thu-nhap-tren-120-150-trieu-donghavu-15779.html | Q28: 2017-06-28 | R28: High | S28: 2026-04-24 21:12:38 ICT | T28: Nguồn xác nhận khoai lang Nhật trồng tại Bắc Giang, không xác nhận riêng SKU hiện tại hoặc chứng nhận GlobalGAP.
A29: B2 | B29: 46 | C29: Khoai lang Nhật | D29: Củ & rễ | E29: Nhật Bản (trồng VN) | F29: Province | G29: Tây Ninh, Việt Nam | H29: Đông Xuân; mô hình phù hợp khí hậu Tây Ninh | I29: 12 | J29: 4 | K29: Đông Xuân | L29: No | M29: Khuyến nông Quốc gia ghi mô hình khoai lang tím Nhật tại Tây Ninh thu hoạch vụ Đông Xuân, phù hợp thổ nhưỡng và khí hậu địa phương. | N29: Khoai lang tím Nhật - Cây trồng tiềm năng cho nông dân Tây Ninh | O29: Trung tâm Khuyến nông Quốc gia | P29: https://khuyennongvn.gov.vn/chuong-trinh-nganh-nong-nghiep/tai-co-cau-nganh-nong-nghiep/khoai-lang-tim-nhat-cay-trong-tiem-nang-cho-nong-dan-tay-ninh-31095.html | Q29: 2025-04-25 | R29: High | S29: 2026-04-24 21:12:38 ICT | T29: Nguồn là khoai lang tím Nhật tại Tây Ninh, không phải mọi loại khoai lang Nhật.
A30: B2 | B30: 52 | C30: Nấm hương khô | D30: Nấm | E30: Trung Quốc | F30: Country | G30: Trung Quốc | H30: Sản phẩm khô/chế biến; mùa vụ tươi phụ thuộc vùng và mô hình trồng | K30: Không áp dụng một mùa bán lẻ cố định | L30: No | M30: FAO ghi Trung Quốc là nhà sản xuất lớn của nấm hương và xuất khẩu nấm hương khô; nguồn không cung cấp lịch mùa vụ chi tiết theo vùng. | N30: Non-Wood Forest Products in 15 Countries of Tropical Asia: An Overview | O30: FAO | P30: https://fao.org/docrep/fao/005/AB598E/AB598E00.pdf | Q30: 2002 | R30: High | S30: 2026-04-24 21:12:38 ICT | T30: Nguồn xác nhận sản xuất/xuất khẩu nấm hương khô Trung Quốc, không xác nhận mùa vụ cụ thể của SKU.
A31: B2 | B31: 53 | C31: Nấm linh chi đỏ | D31: Nấm | E31: Hàn Quốc (trồng VN) | F31: Province | G31: Hòa Bình, Việt Nam | H31: Nuôi trồng theo lứa; lứa đầu khoảng 3 tháng, lứa sau 70-80 ngày | K31: Theo chu kỳ nuôi trồng, không phải mùa tự nhiên cố định | L31: No | M31: Khuyến nông Quốc gia ghi mô hình nấm linh chi đỏ trên giá thể gỗ keo tươi tại Hòa Bình: khoảng 3 tháng cho thu hoạch lứa đầu, một bịch có thể thu 3 lần, lứa sau khoảng 70-80 ngày. | N31: Hòa Bình: Trồng nấm linh chi trên giá thể gỗ keo tươi - mô hình kinh tế hiệu quả | O31: Trung tâm Khuyến nông Quốc gia | P31: https://khuyennongvn.gov.vn/chuong-trinh-nganh-nong-nghiep/tai-co-cau-nganh-nong-nghiep/hoa-binh-trong-nam-linh-chi-tren-gia-the-go-keo-tuoi--mo-hinh-kinh-te-hieu-qua-21892.html | Q31: 2022-06-13 | R31: High | S31: 2026-04-24 21:12:38 ICT | T31: Nguồn xác nhận nấm linh chi đỏ trồng tại Việt Nam, chưa xác nhận giống/nguồn gốc Hàn Quốc của SKU.
A32: B2 | B32: 115 | C32: Tỏi tây | D32: Rau thơm & gia vị | E32: Trung Quốc | F32: Country | G32: Trung Quốc | H32: Allium trồng rộng ở Trung Quốc; chưa có mùa tỏi tây nhập khẩu cụ thể | K32: Cần kiểm chứng thêm theo nhà cung cấp nhập khẩu | L32: No | M32: ISHS ghi nhóm rau Allium là cây rau quan trọng tại Trung Quốc, nhưng dữ liệu công khai tìm được không đủ để xác nhận lịch mùa vụ riêng cho tỏi tây nhập khẩu. | N32: ALLIUM PRODUCTION AND RESEARCH IN CHINA | O32: International Society for Horticultural Science | P32: https://www.ishs.org/ishs-article/358_19 | Q32: 1994 | R32: Medium | S32: 2026-04-24 21:12:38 ICT | T32: Nguồn nói nhóm Allium tại Trung Quốc, không xác nhận riêng tỏi tây/Allium porrum và không có lịch mùa vụ nhập khẩu.
A33: B2 | B33: 121 | C33: khoai mỡ | D33: Rau lá | F33: Province | G33: Vĩnh Long, Việt Nam | H33: Xuống giống sau lúa Đông Xuân; thu sau khoảng 6 tháng | K33: Sau Đông Xuân + 6 tháng | L33: No | M33: Khuyến nông Quốc gia ghi khoai mỡ ở Mang Thít, Vĩnh Long xuống giống khi thu hoạch lúa Đông Xuân và sau 6 tháng trồng thì thu hoạch; có mô hình VietGAP từ Trung tâm Khuyến nông Vĩnh Long. | N33: Vĩnh Long: Tuân thủ kỹ thuật canh tác - Cánh đồng khoai mỡ ngày càng mở rộng | O33: Trung tâm Khuyến nông Quốc gia | P33: https://khuyennongvn.gov.vn/chuong-trinh-nganh-nong-nghiep/tai-co-cau-nganh-nong-nghiep/vinh-long-tuan-thu-ky-thuat-canh-tac--canh-dong-khoai-mo-ngay-cang-mo-rong-19139.html | Q33: 2019-08-22 | R33: High | S33: 2026-04-24 21:12:38 ICT | T33: Dòng catalog thiếu ProductInfo; nguồn không xác nhận origin/standard hiện hành của sản phẩm trong hệ thống.
A34: B2 | B34: 122 | C34: Rau muống | D34: Rau lá | F34: Country | G34: Việt Nam | H34: Có thể sản xuất trong hệ thống thủy canh tuần hoàn; thu hái nhiều lứa | K34: Sau mỗi đợt thu hái bổ sung dinh dưỡng cho lứa sau | L34: No | M34: Khuyến nông Quốc gia ghi rau muống là một trong các giống có thể sản xuất thủy canh tuần hoàn; sau khi hái lứa đầu mới bổ sung dinh dưỡng cho lứa sau. | N34: Quy trình kỹ thuật sản xuất rau thủy canh tuần hoàn | O34: Trung tâm Khuyến nông Quốc gia | P34: https://khuyennongvn.gov.vn/ky-thuat-trong-trot/quy-trinh-ky-thuat-san-xuat-rau-thuy-canh-tuan-hoan-759.html | Q34: 2011-12-26 | R34: High | S34: 2026-04-24 21:12:38 ICT | T34: Dòng catalog thiếu ProductInfo; nguồn là quy trình kỹ thuật thủy canh chung, chưa xác nhận origin/standard hiện hành.

Sheet Research Evidence
A1: Batch | B1: ProductID | C1: ProductName | D1: Field Name | E1: Verified Value / Claim | F1: Applicability / Locality | G1: Source Title | H1: Source Publisher | I1: Source URL | J1: Source Date | K1: Trust Level | L1: Thời gian thu thập | M1: Tôi chưa chắc chắn | N1: Reviewer Notes
A2: B1 | B2: 61 | C2: Táo Fuji Nhật | D2: Origin country | E2: Japan | F2: Product origin | G2: Fruit and Vegetables: Apples | H2: Japan Food Export Fair / Aomori Apple Council | I2: https://j-fec.com/en/producer/pdf/en/20/ | J2: 2022 | K2: High | L2: 2026-04-24 14:43:30 ICT
A3: B1 | B3: 61 | C3: Táo Fuji Nhật | D3: Origin province/region | E3: Aomori Prefecture | F3: Product origin | G3: Fruit and Vegetables: Apples | H3: Japan Food Export Fair / Aomori Apple Council | I3: https://j-fec.com/en/producer/pdf/en/20/ | J3: 2022 | K3: High | L3: 2026-04-24 14:43:30 ICT
